[2024-11-20T03:11:49.505+0100] {local_task_job_runner.py:123} INFO - ::group::Pre task execution logs
[2024-11-20T03:11:49.545+0100] {taskinstance.py:2612} INFO - Dependencies all met for dep_context=non-requeueable deps ti=<TaskInstance: etl_pipeline_to_snowflake.run_data_transformation manual__2024-11-19T00:21:47.385967+00:00 [queued]>
[2024-11-20T03:11:49.578+0100] {taskinstance.py:2612} INFO - Dependencies all met for dep_context=requeueable deps ti=<TaskInstance: etl_pipeline_to_snowflake.run_data_transformation manual__2024-11-19T00:21:47.385967+00:00 [queued]>
[2024-11-20T03:11:49.581+0100] {taskinstance.py:2865} INFO - Starting attempt 38 of 38
[2024-11-20T03:11:49.640+0100] {taskinstance.py:2888} INFO - Executing <Task(PythonOperator): run_data_transformation> on 2024-11-19 00:21:47.385967+00:00
[2024-11-20T03:11:49.656+0100] {standard_task_runner.py:72} INFO - Started process 252562 to run task
[2024-11-20T03:11:49.681+0100] {standard_task_runner.py:104} INFO - Running: ['airflow', 'tasks', 'run', 'etl_pipeline_to_snowflake', 'run_data_transformation', 'manual__2024-11-19T00:21:47.385967+00:00', '--job-id', '106', '--raw', '--subdir', 'DAGS_FOLDER/staging_data_dag.py', '--cfg-path', '/tmp/tmpygnl5tdn']
[2024-11-20T03:11:49.684+0100] {standard_task_runner.py:105} INFO - Job 106: Subtask run_data_transformation
[2024-11-20T03:11:49.807+0100] {task_command.py:467} INFO - Running <TaskInstance: etl_pipeline_to_snowflake.run_data_transformation manual__2024-11-19T00:21:47.385967+00:00 [running]> on host zainab.
[2024-11-20T03:11:49.944+0100] {taskinstance.py:3131} INFO - Exporting env vars: AIRFLOW_CTX_DAG_OWNER='airflow' AIRFLOW_CTX_DAG_ID='etl_pipeline_to_snowflake' AIRFLOW_CTX_TASK_ID='run_data_transformation' AIRFLOW_CTX_EXECUTION_DATE='2024-11-19T00:21:47.385967+00:00' AIRFLOW_CTX_TRY_NUMBER='38' AIRFLOW_CTX_DAG_RUN_ID='manual__2024-11-19T00:21:47.385967+00:00'
[2024-11-20T03:11:49.948+0100] {logging_mixin.py:190} INFO - Task instance is in running state
[2024-11-20T03:11:49.950+0100] {logging_mixin.py:190} INFO -  Previous state of the Task instance: queued
[2024-11-20T03:11:49.956+0100] {logging_mixin.py:190} INFO - Current task name:run_data_transformation state:running start_date:2024-11-20 02:11:49.549002+00:00
[2024-11-20T03:11:49.958+0100] {logging_mixin.py:190} INFO - Dag name:etl_pipeline_to_snowflake and current dag run status:running
[2024-11-20T03:11:49.960+0100] {taskinstance.py:731} INFO - ::endgroup::
[2024-11-20T03:11:50.492+0100] {taskinstance.py:3310} ERROR - Task failed with exception
Traceback (most recent call last):
  File "/mnt/c/Users/zaina/Documents/Core_Data_Engineering/airflow/airflow_coresentiment_Data_pipeline/airflow/lib/python3.10/site-packages/pandas/core/indexes/base.py", line 3791, in get_loc
    return self._engine.get_loc(casted_key)
  File "index.pyx", line 152, in pandas._libs.index.IndexEngine.get_loc
  File "index.pyx", line 181, in pandas._libs.index.IndexEngine.get_loc
  File "pandas/_libs/hashtable_class_helper.pxi", line 7080, in pandas._libs.hashtable.PyObjectHashTable.get_item
  File "pandas/_libs/hashtable_class_helper.pxi", line 7088, in pandas._libs.hashtable.PyObjectHashTable.get_item
KeyError: 'subregion'

The above exception was the direct cause of the following exception:

Traceback (most recent call last):
  File "/mnt/c/Users/zaina/Documents/Core_Data_Engineering/airflow/airflow_coresentiment_Data_pipeline/airflow/lib/python3.10/site-packages/airflow/models/taskinstance.py", line 767, in _execute_task
    result = _execute_callable(context=context, **execute_callable_kwargs)
  File "/mnt/c/Users/zaina/Documents/Core_Data_Engineering/airflow/airflow_coresentiment_Data_pipeline/airflow/lib/python3.10/site-packages/airflow/models/taskinstance.py", line 733, in _execute_callable
    return ExecutionCallableRunner(
  File "/mnt/c/Users/zaina/Documents/Core_Data_Engineering/airflow/airflow_coresentiment_Data_pipeline/airflow/lib/python3.10/site-packages/airflow/utils/operator_helpers.py", line 252, in run
    return self.func(*args, **kwargs)
  File "/mnt/c/Users/zaina/Documents/Core_Data_Engineering/airflow/airflow_coresentiment_Data_pipeline/airflow/lib/python3.10/site-packages/airflow/models/baseoperator.py", line 406, in wrapper
    return func(self, *args, **kwargs)
  File "/mnt/c/Users/zaina/Documents/Core_Data_Engineering/airflow/airflow_coresentiment_Data_pipeline/airflow/lib/python3.10/site-packages/airflow/operators/python.py", line 238, in execute
    return_value = self.execute_callable()
  File "/mnt/c/Users/zaina/Documents/Core_Data_Engineering/airflow/airflow_coresentiment_Data_pipeline/airflow/lib/python3.10/site-packages/airflow/operators/python.py", line 256, in execute_callable
    return runner.run(*self.op_args, **self.op_kwargs)
  File "/mnt/c/Users/zaina/Documents/Core_Data_Engineering/airflow/airflow_coresentiment_Data_pipeline/airflow/lib/python3.10/site-packages/airflow/utils/operator_helpers.py", line 252, in run
    return self.func(*args, **kwargs)
  File "/mnt/c/Users/zaina/Documents/Core_Data_Engineering/capstone_project/airflow/dags/scripts/transform.py", line 102, in run_transformation
    transformed_data = transform_data_s3(data)
  File "/mnt/c/Users/zaina/Documents/Core_Data_Engineering/capstone_project/airflow/dags/scripts/transform.py", line 70, in transform_data_s3
    "Sub_Region": df["subregion"].apply(lambda x: x if x else "No Sub-Region"),  # Use .get() to avoid KeyError if "subregion" is missing
  File "/mnt/c/Users/zaina/Documents/Core_Data_Engineering/airflow/airflow_coresentiment_Data_pipeline/airflow/lib/python3.10/site-packages/pandas/core/frame.py", line 3893, in __getitem__
    indexer = self.columns.get_loc(key)
  File "/mnt/c/Users/zaina/Documents/Core_Data_Engineering/airflow/airflow_coresentiment_Data_pipeline/airflow/lib/python3.10/site-packages/pandas/core/indexes/base.py", line 3798, in get_loc
    raise KeyError(key) from err
KeyError: 'subregion'
[2024-11-20T03:11:51.029+0100] {logging_mixin.py:190} INFO - Task instance in failure state
[2024-11-20T03:11:51.032+0100] {logging_mixin.py:190} INFO - Task start:2024-11-20 02:11:49.549002+00:00 end:2024-11-20 02:11:51.028451+00:00 duration:1.479449
[2024-11-20T03:11:51.035+0100] {logging_mixin.py:190} INFO - Task:<Task(PythonOperator): run_data_transformation> dag:<DAG: etl_pipeline_to_snowflake> dagrun:<DagRun etl_pipeline_to_snowflake @ 2024-11-19 00:21:47.385967+00:00: manual__2024-11-19T00:21:47.385967+00:00, state:running, queued_at: 2024-11-20 02:03:01.748341+00:00. externally triggered: True>
[2024-11-20T03:11:51.044+0100] {logging_mixin.py:190} INFO - Failure caused by 'subregion'
[2024-11-20T03:11:51.047+0100] {taskinstance.py:1225} INFO - Marking task as FAILED. dag_id=etl_pipeline_to_snowflake, task_id=run_data_transformation, run_id=manual__2024-11-19T00:21:47.385967+00:00, execution_date=20241119T002147, start_date=20241120T021149, end_date=20241120T021151
[2024-11-20T03:11:51.478+0100] {taskinstance.py:340} INFO - ::group::Post task execution logs
[2024-11-20T03:11:51.480+0100] {standard_task_runner.py:124} ERROR - Failed to execute job 106 for task run_data_transformation ('subregion'; 252562)
Traceback (most recent call last):
  File "/mnt/c/Users/zaina/Documents/Core_Data_Engineering/airflow/airflow_coresentiment_Data_pipeline/airflow/lib/python3.10/site-packages/pandas/core/indexes/base.py", line 3791, in get_loc
    return self._engine.get_loc(casted_key)
  File "index.pyx", line 152, in pandas._libs.index.IndexEngine.get_loc
  File "index.pyx", line 181, in pandas._libs.index.IndexEngine.get_loc
  File "pandas/_libs/hashtable_class_helper.pxi", line 7080, in pandas._libs.hashtable.PyObjectHashTable.get_item
  File "pandas/_libs/hashtable_class_helper.pxi", line 7088, in pandas._libs.hashtable.PyObjectHashTable.get_item
KeyError: 'subregion'

The above exception was the direct cause of the following exception:

Traceback (most recent call last):
  File "/mnt/c/Users/zaina/Documents/Core_Data_Engineering/airflow/airflow_coresentiment_Data_pipeline/airflow/lib/python3.10/site-packages/airflow/task/task_runner/standard_task_runner.py", line 117, in _start_by_fork
    ret = args.func(args, dag=self.dag)
  File "/mnt/c/Users/zaina/Documents/Core_Data_Engineering/airflow/airflow_coresentiment_Data_pipeline/airflow/lib/python3.10/site-packages/airflow/cli/cli_config.py", line 49, in command
    return func(*args, **kwargs)
  File "/mnt/c/Users/zaina/Documents/Core_Data_Engineering/airflow/airflow_coresentiment_Data_pipeline/airflow/lib/python3.10/site-packages/airflow/utils/cli.py", line 115, in wrapper
    return f(*args, **kwargs)
  File "/mnt/c/Users/zaina/Documents/Core_Data_Engineering/airflow/airflow_coresentiment_Data_pipeline/airflow/lib/python3.10/site-packages/airflow/cli/commands/task_command.py", line 483, in task_run
    task_return_code = _run_task_by_selected_method(args, _dag, ti)
  File "/mnt/c/Users/zaina/Documents/Core_Data_Engineering/airflow/airflow_coresentiment_Data_pipeline/airflow/lib/python3.10/site-packages/airflow/cli/commands/task_command.py", line 256, in _run_task_by_selected_method
    return _run_raw_task(args, ti)
  File "/mnt/c/Users/zaina/Documents/Core_Data_Engineering/airflow/airflow_coresentiment_Data_pipeline/airflow/lib/python3.10/site-packages/airflow/cli/commands/task_command.py", line 341, in _run_raw_task
    return ti._run_raw_task(
  File "/mnt/c/Users/zaina/Documents/Core_Data_Engineering/airflow/airflow_coresentiment_Data_pipeline/airflow/lib/python3.10/site-packages/airflow/utils/session.py", line 97, in wrapper
    return func(*args, session=session, **kwargs)
  File "/mnt/c/Users/zaina/Documents/Core_Data_Engineering/airflow/airflow_coresentiment_Data_pipeline/airflow/lib/python3.10/site-packages/airflow/models/taskinstance.py", line 3004, in _run_raw_task
    return _run_raw_task(
  File "/mnt/c/Users/zaina/Documents/Core_Data_Engineering/airflow/airflow_coresentiment_Data_pipeline/airflow/lib/python3.10/site-packages/airflow/models/taskinstance.py", line 273, in _run_raw_task
    TaskInstance._execute_task_with_callbacks(
  File "/mnt/c/Users/zaina/Documents/Core_Data_Engineering/airflow/airflow_coresentiment_Data_pipeline/airflow/lib/python3.10/site-packages/airflow/models/taskinstance.py", line 3158, in _execute_task_with_callbacks
    result = self._execute_task(context, task_orig)
  File "/mnt/c/Users/zaina/Documents/Core_Data_Engineering/airflow/airflow_coresentiment_Data_pipeline/airflow/lib/python3.10/site-packages/airflow/models/taskinstance.py", line 3182, in _execute_task
    return _execute_task(self, context, task_orig)
  File "/mnt/c/Users/zaina/Documents/Core_Data_Engineering/airflow/airflow_coresentiment_Data_pipeline/airflow/lib/python3.10/site-packages/airflow/models/taskinstance.py", line 767, in _execute_task
    result = _execute_callable(context=context, **execute_callable_kwargs)
  File "/mnt/c/Users/zaina/Documents/Core_Data_Engineering/airflow/airflow_coresentiment_Data_pipeline/airflow/lib/python3.10/site-packages/airflow/models/taskinstance.py", line 733, in _execute_callable
    return ExecutionCallableRunner(
  File "/mnt/c/Users/zaina/Documents/Core_Data_Engineering/airflow/airflow_coresentiment_Data_pipeline/airflow/lib/python3.10/site-packages/airflow/utils/operator_helpers.py", line 252, in run
    return self.func(*args, **kwargs)
  File "/mnt/c/Users/zaina/Documents/Core_Data_Engineering/airflow/airflow_coresentiment_Data_pipeline/airflow/lib/python3.10/site-packages/airflow/models/baseoperator.py", line 406, in wrapper
    return func(self, *args, **kwargs)
  File "/mnt/c/Users/zaina/Documents/Core_Data_Engineering/airflow/airflow_coresentiment_Data_pipeline/airflow/lib/python3.10/site-packages/airflow/operators/python.py", line 238, in execute
    return_value = self.execute_callable()
  File "/mnt/c/Users/zaina/Documents/Core_Data_Engineering/airflow/airflow_coresentiment_Data_pipeline/airflow/lib/python3.10/site-packages/airflow/operators/python.py", line 256, in execute_callable
    return runner.run(*self.op_args, **self.op_kwargs)
  File "/mnt/c/Users/zaina/Documents/Core_Data_Engineering/airflow/airflow_coresentiment_Data_pipeline/airflow/lib/python3.10/site-packages/airflow/utils/operator_helpers.py", line 252, in run
    return self.func(*args, **kwargs)
  File "/mnt/c/Users/zaina/Documents/Core_Data_Engineering/capstone_project/airflow/dags/scripts/transform.py", line 102, in run_transformation
    transformed_data = transform_data_s3(data)
  File "/mnt/c/Users/zaina/Documents/Core_Data_Engineering/capstone_project/airflow/dags/scripts/transform.py", line 70, in transform_data_s3
    "Sub_Region": df["subregion"].apply(lambda x: x if x else "No Sub-Region"),  # Use .get() to avoid KeyError if "subregion" is missing
  File "/mnt/c/Users/zaina/Documents/Core_Data_Engineering/airflow/airflow_coresentiment_Data_pipeline/airflow/lib/python3.10/site-packages/pandas/core/frame.py", line 3893, in __getitem__
    indexer = self.columns.get_loc(key)
  File "/mnt/c/Users/zaina/Documents/Core_Data_Engineering/airflow/airflow_coresentiment_Data_pipeline/airflow/lib/python3.10/site-packages/pandas/core/indexes/base.py", line 3798, in get_loc
    raise KeyError(key) from err
KeyError: 'subregion'
[2024-11-20T03:11:52.032+0100] {local_task_job_runner.py:266} INFO - Task exited with return code 1
[2024-11-20T03:11:52.059+0100] {taskinstance.py:3900} INFO - 0 downstream tasks scheduled from follow-on schedule check
[2024-11-20T03:11:52.064+0100] {local_task_job_runner.py:245} INFO - ::endgroup::
