[2024-11-19T20:47:46.522+0100] {local_task_job_runner.py:123} INFO - ::group::Pre task execution logs
[2024-11-19T20:47:46.561+0100] {taskinstance.py:2612} INFO - Dependencies all met for dep_context=non-requeueable deps ti=<TaskInstance: etl_pipeline_to_snowflake.run_data_transformation manual__2024-11-19T00:21:47.385967+00:00 [queued]>
[2024-11-19T20:47:46.583+0100] {taskinstance.py:2612} INFO - Dependencies all met for dep_context=requeueable deps ti=<TaskInstance: etl_pipeline_to_snowflake.run_data_transformation manual__2024-11-19T00:21:47.385967+00:00 [queued]>
[2024-11-19T20:47:46.586+0100] {taskinstance.py:2865} INFO - Starting attempt 24 of 25
[2024-11-19T20:47:46.642+0100] {taskinstance.py:2888} INFO - Executing <Task(PythonOperator): run_data_transformation> on 2024-11-19 00:21:47.385967+00:00
[2024-11-19T20:47:46.654+0100] {standard_task_runner.py:72} INFO - Started process 241298 to run task
[2024-11-19T20:47:46.659+0100] {standard_task_runner.py:104} INFO - Running: ['airflow', 'tasks', 'run', 'etl_pipeline_to_snowflake', 'run_data_transformation', 'manual__2024-11-19T00:21:47.385967+00:00', '--job-id', '77', '--raw', '--subdir', 'DAGS_FOLDER/staging_data_dag.py', '--cfg-path', '/tmp/tmpvy2xh8gg']
[2024-11-19T20:47:46.662+0100] {standard_task_runner.py:105} INFO - Job 77: Subtask run_data_transformation
[2024-11-19T20:47:46.840+0100] {task_command.py:467} INFO - Running <TaskInstance: etl_pipeline_to_snowflake.run_data_transformation manual__2024-11-19T00:21:47.385967+00:00 [running]> on host zainab.
[2024-11-19T20:47:46.972+0100] {taskinstance.py:3131} INFO - Exporting env vars: AIRFLOW_CTX_DAG_OWNER='airflow' AIRFLOW_CTX_DAG_ID='etl_pipeline_to_snowflake' AIRFLOW_CTX_TASK_ID='run_data_transformation' AIRFLOW_CTX_EXECUTION_DATE='2024-11-19T00:21:47.385967+00:00' AIRFLOW_CTX_TRY_NUMBER='24' AIRFLOW_CTX_DAG_RUN_ID='manual__2024-11-19T00:21:47.385967+00:00'
[2024-11-19T20:47:46.977+0100] {logging_mixin.py:190} INFO - Task instance is in running state
[2024-11-19T20:47:46.979+0100] {logging_mixin.py:190} INFO -  Previous state of the Task instance: queued
[2024-11-19T20:47:46.983+0100] {logging_mixin.py:190} INFO - Current task name:run_data_transformation state:running start_date:2024-11-19 19:47:46.566063+00:00
[2024-11-19T20:47:46.985+0100] {logging_mixin.py:190} INFO - Dag name:etl_pipeline_to_snowflake and current dag run status:running
[2024-11-19T20:47:46.987+0100] {taskinstance.py:731} INFO - ::endgroup::
[2024-11-19T20:47:47.492+0100] {transform.py:36} INFO - Transformation complete.
[2024-11-19T20:47:47.519+0100] {base.py:84} INFO - Retrieving connection 'snowflake_conn_id'
[2024-11-19T20:47:47.524+0100] {connection.py:414} INFO - Snowflake Connector for Python Version: 3.12.3, Python Version: 3.10.12, Platform: Linux-5.15.167.4-microsoft-standard-WSL2-x86_64-with-glibc2.35
[2024-11-19T20:47:47.528+0100] {connection.py:1197} INFO - Connecting to GLOBAL Snowflake domain
[2024-11-19T20:47:47.533+0100] {connection.py:1278} INFO - This connection is in OCSP Fail Open Mode. TLS Certificates would be checked for validity and revocation status. Any other Certificate Revocation related exceptions or OCSP Responder failures would be disregarded in favor of connectivity.
[2024-11-19T20:47:49.670+0100] {connection.py:547} WARNING - Certificate did not match expected hostname: ek32444.aws_eu_central_1.snowflakecomputing.com. Certificate: {'subject': ((('commonName', '*.prod3.us-west-2.snowflakecomputing.com'),),), 'subjectAltName': [('DNS', '*.prod3.us-west-2.snowflakecomputing.com'), ('DNS', '*.us-west-2.snowflakecomputing.com'), ('DNS', '*.global.snowflakecomputing.com'), ('DNS', '*.snowflakecomputing.com'), ('DNS', '*.prod3.us-west-2.aws.snowflakecomputing.com')]}
[2024-11-19T20:47:49.673+0100] {connectionpool.py:824} WARNING - Retrying (Retry(total=0, connect=None, read=None, redirect=None, status=None)) after connection broken by 'SSLError(CertificateError("hostname 'ek32444.aws_eu_central_1.snowflakecomputing.com' doesn't match either of '*.prod3.us-west-2.snowflakecomputing.com', '*.us-west-2.snowflakecomputing.com', '*.global.snowflakecomputing.com', '*.snowflakecomputing.com', '*.prod3.us-west-2.aws.snowflakecomputing.com'"))': /session/v1/login-request?request_id=f11ded67-d00e-4f57-b40d-108d35a8fac0&databaseName=country_data&schemaName=staging&warehouse=compute_wh&roleName=ACCOUNTADMIN&request_guid=035e55a2-8f6d-443e-9fd2-7237905f43b3
[2024-11-19T20:47:51.345+0100] {connection.py:547} WARNING - Certificate did not match expected hostname: ek32444.aws_eu_central_1.snowflakecomputing.com. Certificate: {'subject': ((('commonName', '*.prod3.us-west-2.snowflakecomputing.com'),),), 'subjectAltName': [('DNS', '*.prod3.us-west-2.snowflakecomputing.com'), ('DNS', '*.us-west-2.snowflakecomputing.com'), ('DNS', '*.global.snowflakecomputing.com'), ('DNS', '*.snowflakecomputing.com'), ('DNS', '*.prod3.us-west-2.aws.snowflakecomputing.com')]}
[2024-11-19T20:47:53.744+0100] {connection.py:547} WARNING - Certificate did not match expected hostname: ek32444.aws_eu_central_1.snowflakecomputing.com. Certificate: {'subject': ((('commonName', '*.prod3.us-west-2.snowflakecomputing.com'),),), 'subjectAltName': [('DNS', '*.prod3.us-west-2.snowflakecomputing.com'), ('DNS', '*.us-west-2.snowflakecomputing.com'), ('DNS', '*.global.snowflakecomputing.com'), ('DNS', '*.snowflakecomputing.com'), ('DNS', '*.prod3.us-west-2.aws.snowflakecomputing.com')]}
[2024-11-19T20:47:53.752+0100] {connectionpool.py:824} WARNING - Retrying (Retry(total=0, connect=None, read=None, redirect=None, status=None)) after connection broken by 'SSLError(CertificateError("hostname 'ek32444.aws_eu_central_1.snowflakecomputing.com' doesn't match either of '*.prod3.us-west-2.snowflakecomputing.com', '*.us-west-2.snowflakecomputing.com', '*.global.snowflakecomputing.com', '*.snowflakecomputing.com', '*.prod3.us-west-2.aws.snowflakecomputing.com'"))': /session/v1/login-request?request_id=13b67f65-928a-41b1-8271-1cb55d3f4ed7&databaseName=country_data&schemaName=staging&warehouse=compute_wh&roleName=ACCOUNTADMIN&request_guid=55a34caa-0b1c-43ca-b9f0-21f06b632aa3
[2024-11-19T20:47:54.767+0100] {connection.py:547} WARNING - Certificate did not match expected hostname: ek32444.aws_eu_central_1.snowflakecomputing.com. Certificate: {'subject': ((('commonName', '*.prod3.us-west-2.snowflakecomputing.com'),),), 'subjectAltName': [('DNS', '*.prod3.us-west-2.snowflakecomputing.com'), ('DNS', '*.us-west-2.snowflakecomputing.com'), ('DNS', '*.global.snowflakecomputing.com'), ('DNS', '*.snowflakecomputing.com'), ('DNS', '*.prod3.us-west-2.aws.snowflakecomputing.com')]}
[2024-11-19T20:47:55.119+0100] {taskinstance.py:3310} ERROR - Task failed with exception
Traceback (most recent call last):
  File "/mnt/c/Users/zaina/Documents/Core_Data_Engineering/airflow/airflow_coresentiment_Data_pipeline/airflow/lib/python3.10/site-packages/snowflake/connector/vendored/urllib3/connectionpool.py", line 715, in urlopen
    httplib_response = self._make_request(
  File "/mnt/c/Users/zaina/Documents/Core_Data_Engineering/airflow/airflow_coresentiment_Data_pipeline/airflow/lib/python3.10/site-packages/snowflake/connector/vendored/urllib3/connectionpool.py", line 404, in _make_request
    self._validate_conn(conn)
  File "/mnt/c/Users/zaina/Documents/Core_Data_Engineering/airflow/airflow_coresentiment_Data_pipeline/airflow/lib/python3.10/site-packages/snowflake/connector/vendored/urllib3/connectionpool.py", line 1058, in _validate_conn
    conn.connect()
  File "/mnt/c/Users/zaina/Documents/Core_Data_Engineering/airflow/airflow_coresentiment_Data_pipeline/airflow/lib/python3.10/site-packages/snowflake/connector/vendored/urllib3/connection.py", line 472, in connect
    _match_hostname(cert, self.assert_hostname or server_hostname)
  File "/mnt/c/Users/zaina/Documents/Core_Data_Engineering/airflow/airflow_coresentiment_Data_pipeline/airflow/lib/python3.10/site-packages/snowflake/connector/vendored/urllib3/connection.py", line 545, in _match_hostname
    match_hostname(cert, asserted_hostname)
  File "/mnt/c/Users/zaina/Documents/Core_Data_Engineering/airflow/airflow_coresentiment_Data_pipeline/airflow/lib/python3.10/site-packages/snowflake/connector/vendored/urllib3/util/ssl_match_hostname.py", line 150, in match_hostname
    raise CertificateError(
snowflake.connector.vendored.urllib3.util.ssl_match_hostname.CertificateError: hostname 'ek32444.aws_eu_central_1.snowflakecomputing.com' doesn't match either of '*.prod3.us-west-2.snowflakecomputing.com', '*.us-west-2.snowflakecomputing.com', '*.global.snowflakecomputing.com', '*.snowflakecomputing.com', '*.prod3.us-west-2.aws.snowflakecomputing.com'

During handling of the above exception, another exception occurred:

Traceback (most recent call last):
  File "/mnt/c/Users/zaina/Documents/Core_Data_Engineering/airflow/airflow_coresentiment_Data_pipeline/airflow/lib/python3.10/site-packages/snowflake/connector/vendored/requests/adapters.py", line 486, in send
    resp = conn.urlopen(
  File "/mnt/c/Users/zaina/Documents/Core_Data_Engineering/airflow/airflow_coresentiment_Data_pipeline/airflow/lib/python3.10/site-packages/snowflake/connector/vendored/urllib3/connectionpool.py", line 827, in urlopen
    return self.urlopen(
  File "/mnt/c/Users/zaina/Documents/Core_Data_Engineering/airflow/airflow_coresentiment_Data_pipeline/airflow/lib/python3.10/site-packages/snowflake/connector/vendored/urllib3/connectionpool.py", line 799, in urlopen
    retries = retries.increment(
  File "/mnt/c/Users/zaina/Documents/Core_Data_Engineering/airflow/airflow_coresentiment_Data_pipeline/airflow/lib/python3.10/site-packages/snowflake/connector/vendored/urllib3/util/retry.py", line 592, in increment
    raise MaxRetryError(_pool, url, error or ResponseError(cause))
snowflake.connector.vendored.urllib3.exceptions.MaxRetryError: HTTPSConnectionPool(host='ek32444.aws_eu_central_1.snowflakecomputing.com', port=443): Max retries exceeded with url: /session/v1/login-request?request_id=f11ded67-d00e-4f57-b40d-108d35a8fac0&databaseName=country_data&schemaName=staging&warehouse=compute_wh&roleName=ACCOUNTADMIN&request_guid=035e55a2-8f6d-443e-9fd2-7237905f43b3 (Caused by SSLError(CertificateError("hostname 'ek32444.aws_eu_central_1.snowflakecomputing.com' doesn't match either of '*.prod3.us-west-2.snowflakecomputing.com', '*.us-west-2.snowflakecomputing.com', '*.global.snowflakecomputing.com', '*.snowflakecomputing.com', '*.prod3.us-west-2.aws.snowflakecomputing.com'")))

During handling of the above exception, another exception occurred:

Traceback (most recent call last):
  File "/mnt/c/Users/zaina/Documents/Core_Data_Engineering/airflow/airflow_coresentiment_Data_pipeline/airflow/lib/python3.10/site-packages/snowflake/connector/network.py", line 1072, in _request_exec
    raw_ret = session.request(
  File "/mnt/c/Users/zaina/Documents/Core_Data_Engineering/airflow/airflow_coresentiment_Data_pipeline/airflow/lib/python3.10/site-packages/snowflake/connector/vendored/requests/sessions.py", line 589, in request
    resp = self.send(prep, **send_kwargs)
  File "/mnt/c/Users/zaina/Documents/Core_Data_Engineering/airflow/airflow_coresentiment_Data_pipeline/airflow/lib/python3.10/site-packages/snowflake/connector/vendored/requests/sessions.py", line 703, in send
    r = adapter.send(request, **kwargs)
  File "/mnt/c/Users/zaina/Documents/Core_Data_Engineering/airflow/airflow_coresentiment_Data_pipeline/airflow/lib/python3.10/site-packages/snowflake/connector/vendored/requests/adapters.py", line 517, in send
    raise SSLError(e, request=request)
snowflake.connector.vendored.requests.exceptions.SSLError: HTTPSConnectionPool(host='ek32444.aws_eu_central_1.snowflakecomputing.com', port=443): Max retries exceeded with url: /session/v1/login-request?request_id=f11ded67-d00e-4f57-b40d-108d35a8fac0&databaseName=country_data&schemaName=staging&warehouse=compute_wh&roleName=ACCOUNTADMIN&request_guid=035e55a2-8f6d-443e-9fd2-7237905f43b3 (Caused by SSLError(CertificateError("hostname 'ek32444.aws_eu_central_1.snowflakecomputing.com' doesn't match either of '*.prod3.us-west-2.snowflakecomputing.com', '*.us-west-2.snowflakecomputing.com', '*.global.snowflakecomputing.com', '*.snowflakecomputing.com', '*.prod3.us-west-2.aws.snowflakecomputing.com'")))

During handling of the above exception, another exception occurred:

Traceback (most recent call last):
  File "/mnt/c/Users/zaina/Documents/Core_Data_Engineering/airflow/airflow_coresentiment_Data_pipeline/airflow/lib/python3.10/site-packages/snowflake/connector/connection.py", line 1415, in _authenticate
    auth.authenticate(
  File "/mnt/c/Users/zaina/Documents/Core_Data_Engineering/airflow/airflow_coresentiment_Data_pipeline/airflow/lib/python3.10/site-packages/snowflake/connector/auth/_auth.py", line 264, in authenticate
    ret = self._rest._post_request(
  File "/mnt/c/Users/zaina/Documents/Core_Data_Engineering/airflow/airflow_coresentiment_Data_pipeline/airflow/lib/python3.10/site-packages/snowflake/connector/network.py", line 740, in _post_request
    ret = self.fetch(
  File "/mnt/c/Users/zaina/Documents/Core_Data_Engineering/airflow/airflow_coresentiment_Data_pipeline/airflow/lib/python3.10/site-packages/snowflake/connector/network.py", line 855, in fetch
    ret = self._request_exec_wrapper(
  File "/mnt/c/Users/zaina/Documents/Core_Data_Engineering/airflow/airflow_coresentiment_Data_pipeline/airflow/lib/python3.10/site-packages/snowflake/connector/network.py", line 983, in _request_exec_wrapper
    raise e
  File "/mnt/c/Users/zaina/Documents/Core_Data_Engineering/airflow/airflow_coresentiment_Data_pipeline/airflow/lib/python3.10/site-packages/snowflake/connector/network.py", line 905, in _request_exec_wrapper
    return_object = self._request_exec(
  File "/mnt/c/Users/zaina/Documents/Core_Data_Engineering/airflow/airflow_coresentiment_Data_pipeline/airflow/lib/python3.10/site-packages/snowflake/connector/network.py", line 1142, in _request_exec
    Error.errorhandler_wrapper(
  File "/mnt/c/Users/zaina/Documents/Core_Data_Engineering/airflow/airflow_coresentiment_Data_pipeline/airflow/lib/python3.10/site-packages/snowflake/connector/errors.py", line 284, in errorhandler_wrapper
    handed_over = Error.hand_to_other_handler(
  File "/mnt/c/Users/zaina/Documents/Core_Data_Engineering/airflow/airflow_coresentiment_Data_pipeline/airflow/lib/python3.10/site-packages/snowflake/connector/errors.py", line 342, in hand_to_other_handler
    connection.errorhandler(connection, cursor, error_class, error_value)
  File "/mnt/c/Users/zaina/Documents/Core_Data_Engineering/airflow/airflow_coresentiment_Data_pipeline/airflow/lib/python3.10/site-packages/snowflake/connector/errors.py", line 215, in default_errorhandler
    raise error_class(
snowflake.connector.errors.OperationalError: 250003: 250003: Hit non-retryable SSL error, HTTPSConnectionPool(host='ek32444.aws_eu_central_1.snowflakecomputing.com', port=443): Max retries exceeded with url: /session/v1/login-request?request_id=f11ded67-d00e-4f57-b40d-108d35a8fac0&databaseName=country_data&schemaName=staging&warehouse=compute_wh&roleName=ACCOUNTADMIN&request_guid=035e55a2-8f6d-443e-9fd2-7237905f43b3 (Caused by SSLError(CertificateError("hostname 'ek32444.aws_eu_central_1.snowflakecomputing.com' doesn't match either of '*.prod3.us-west-2.snowflakecomputing.com', '*.us-west-2.snowflakecomputing.com', '*.global.snowflakecomputing.com', '*.snowflakecomputing.com', '*.prod3.us-west-2.aws.snowflakecomputing.com'"))).
Verify that the hostnames and port numbers in SYSTEM$ALLOWLIST are added to your firewall's allowed list.
To further troubleshoot your connection you may reference the following article: https://docs.snowflake.com/en/user-guide/client-connectivity-troubleshooting/overview.

The above exception was the direct cause of the following exception:

Traceback (most recent call last):
  File "/mnt/c/Users/zaina/Documents/Core_Data_Engineering/airflow/airflow_coresentiment_Data_pipeline/airflow/lib/python3.10/site-packages/airflow/models/taskinstance.py", line 767, in _execute_task
    result = _execute_callable(context=context, **execute_callable_kwargs)
  File "/mnt/c/Users/zaina/Documents/Core_Data_Engineering/airflow/airflow_coresentiment_Data_pipeline/airflow/lib/python3.10/site-packages/airflow/models/taskinstance.py", line 733, in _execute_callable
    return ExecutionCallableRunner(
  File "/mnt/c/Users/zaina/Documents/Core_Data_Engineering/airflow/airflow_coresentiment_Data_pipeline/airflow/lib/python3.10/site-packages/airflow/utils/operator_helpers.py", line 252, in run
    return self.func(*args, **kwargs)
  File "/mnt/c/Users/zaina/Documents/Core_Data_Engineering/airflow/airflow_coresentiment_Data_pipeline/airflow/lib/python3.10/site-packages/airflow/models/baseoperator.py", line 406, in wrapper
    return func(self, *args, **kwargs)
  File "/mnt/c/Users/zaina/Documents/Core_Data_Engineering/airflow/airflow_coresentiment_Data_pipeline/airflow/lib/python3.10/site-packages/airflow/operators/python.py", line 238, in execute
    return_value = self.execute_callable()
  File "/mnt/c/Users/zaina/Documents/Core_Data_Engineering/airflow/airflow_coresentiment_Data_pipeline/airflow/lib/python3.10/site-packages/airflow/operators/python.py", line 256, in execute_callable
    return runner.run(*self.op_args, **self.op_kwargs)
  File "/mnt/c/Users/zaina/Documents/Core_Data_Engineering/airflow/airflow_coresentiment_Data_pipeline/airflow/lib/python3.10/site-packages/airflow/utils/operator_helpers.py", line 252, in run
    return self.func(*args, **kwargs)
  File "/mnt/c/Users/zaina/Documents/Core_Data_Engineering/capstone_project/airflow/dags/scripts/transform.py", line 95, in run_transformation
    load_function(
  File "/mnt/c/Users/zaina/Documents/Core_Data_Engineering/capstone_project/airflow/dags/scripts/load.py", line 74, in load_data_to_snowflake
    result = snowflake_hook.get_first(check_table_query)
  File "/mnt/c/Users/zaina/Documents/Core_Data_Engineering/airflow/airflow_coresentiment_Data_pipeline/airflow/lib/python3.10/site-packages/airflow/providers/common/sql/hooks/sql.py", line 367, in get_first
    return self.run(sql=sql, parameters=parameters, handler=fetch_one_handler)
  File "/mnt/c/Users/zaina/Documents/Core_Data_Engineering/airflow/airflow_coresentiment_Data_pipeline/airflow/lib/python3.10/site-packages/airflow/providers/snowflake/hooks/snowflake.py", line 429, in run
    with closing(self.get_conn()) as conn:
  File "/mnt/c/Users/zaina/Documents/Core_Data_Engineering/airflow/airflow_coresentiment_Data_pipeline/airflow/lib/python3.10/site-packages/airflow/providers/snowflake/hooks/snowflake.py", line 303, in get_conn
    conn = connector.connect(**conn_config)
  File "/mnt/c/Users/zaina/Documents/Core_Data_Engineering/airflow/airflow_coresentiment_Data_pipeline/airflow/lib/python3.10/site-packages/snowflake/connector/__init__.py", line 55, in Connect
    return SnowflakeConnection(**kwargs)
  File "/mnt/c/Users/zaina/Documents/Core_Data_Engineering/airflow/airflow_coresentiment_Data_pipeline/airflow/lib/python3.10/site-packages/snowflake/connector/connection.py", line 457, in __init__
    self.connect(**kwargs)
  File "/mnt/c/Users/zaina/Documents/Core_Data_Engineering/airflow/airflow_coresentiment_Data_pipeline/airflow/lib/python3.10/site-packages/snowflake/connector/connection.py", line 772, in connect
    self.__open_connection()
  File "/mnt/c/Users/zaina/Documents/Core_Data_Engineering/airflow/airflow_coresentiment_Data_pipeline/airflow/lib/python3.10/site-packages/snowflake/connector/connection.py", line 1100, in __open_connection
    self.authenticate_with_retry(self.auth_class)
  File "/mnt/c/Users/zaina/Documents/Core_Data_Engineering/airflow/airflow_coresentiment_Data_pipeline/airflow/lib/python3.10/site-packages/snowflake/connector/connection.py", line 1387, in authenticate_with_retry
    self._authenticate(auth_instance)
  File "/mnt/c/Users/zaina/Documents/Core_Data_Engineering/airflow/airflow_coresentiment_Data_pipeline/airflow/lib/python3.10/site-packages/snowflake/connector/connection.py", line 1461, in _authenticate
    raise auth_op from e
  File "/mnt/c/Users/zaina/Documents/Core_Data_Engineering/airflow/airflow_coresentiment_Data_pipeline/airflow/lib/python3.10/site-packages/snowflake/connector/connection.py", line 1436, in _authenticate
    auth_instance.handle_timeout(
  File "/mnt/c/Users/zaina/Documents/Core_Data_Engineering/airflow/airflow_coresentiment_Data_pipeline/airflow/lib/python3.10/site-packages/snowflake/connector/auth/by_plugin.py", line 212, in handle_timeout
    raise error
snowflake.connector.errors.OperationalError: 250001: 250001: Could not connect to Snowflake backend after 2 attempt(s).Aborting
Verify that the hostnames and port numbers in SYSTEM$ALLOWLIST are added to your firewall's allowed list.
To further troubleshoot your connection you may reference the following article: https://docs.snowflake.com/en/user-guide/client-connectivity-troubleshooting/overview.
[2024-11-19T20:47:55.703+0100] {logging_mixin.py:190} INFO - Task instance in failure state
[2024-11-19T20:47:55.708+0100] {logging_mixin.py:190} INFO - Task start:2024-11-19 19:47:46.566063+00:00 end:2024-11-19 19:47:55.702544+00:00 duration:9.136481
[2024-11-19T20:47:55.716+0100] {logging_mixin.py:190} INFO - Task:<Task(PythonOperator): run_data_transformation> dag:<DAG: etl_pipeline_to_snowflake> dagrun:<DagRun etl_pipeline_to_snowflake @ 2024-11-19 00:21:47.385967+00:00: manual__2024-11-19T00:21:47.385967+00:00, state:running, queued_at: 2024-11-19 19:46:36.941467+00:00. externally triggered: True>
[2024-11-19T20:47:55.722+0100] {logging_mixin.py:190} INFO - Failure caused by 250001: 250001: Could not connect to Snowflake backend after 2 attempt(s).Aborting
Verify that the hostnames and port numbers in SYSTEM$ALLOWLIST are added to your firewall's allowed list.
To further troubleshoot your connection you may reference the following article: https://docs.snowflake.com/en/user-guide/client-connectivity-troubleshooting/overview.
[2024-11-19T20:47:55.726+0100] {taskinstance.py:1225} INFO - Marking task as UP_FOR_RETRY. dag_id=etl_pipeline_to_snowflake, task_id=run_data_transformation, run_id=manual__2024-11-19T00:21:47.385967+00:00, execution_date=20241119T002147, start_date=20241119T194746, end_date=20241119T194755
[2024-11-19T20:47:55.872+0100] {taskinstance.py:340} INFO - ::group::Post task execution logs
[2024-11-19T20:47:55.883+0100] {standard_task_runner.py:124} ERROR - Failed to execute job 77 for task run_data_transformation (250001: 250001: Could not connect to Snowflake backend after 2 attempt(s).Aborting
Verify that the hostnames and port numbers in SYSTEM$ALLOWLIST are added to your firewall's allowed list.
To further troubleshoot your connection you may reference the following article: https://docs.snowflake.com/en/user-guide/client-connectivity-troubleshooting/overview.; 241298)
Traceback (most recent call last):
  File "/mnt/c/Users/zaina/Documents/Core_Data_Engineering/airflow/airflow_coresentiment_Data_pipeline/airflow/lib/python3.10/site-packages/snowflake/connector/vendored/urllib3/connectionpool.py", line 715, in urlopen
    httplib_response = self._make_request(
  File "/mnt/c/Users/zaina/Documents/Core_Data_Engineering/airflow/airflow_coresentiment_Data_pipeline/airflow/lib/python3.10/site-packages/snowflake/connector/vendored/urllib3/connectionpool.py", line 404, in _make_request
    self._validate_conn(conn)
  File "/mnt/c/Users/zaina/Documents/Core_Data_Engineering/airflow/airflow_coresentiment_Data_pipeline/airflow/lib/python3.10/site-packages/snowflake/connector/vendored/urllib3/connectionpool.py", line 1058, in _validate_conn
    conn.connect()
  File "/mnt/c/Users/zaina/Documents/Core_Data_Engineering/airflow/airflow_coresentiment_Data_pipeline/airflow/lib/python3.10/site-packages/snowflake/connector/vendored/urllib3/connection.py", line 472, in connect
    _match_hostname(cert, self.assert_hostname or server_hostname)
  File "/mnt/c/Users/zaina/Documents/Core_Data_Engineering/airflow/airflow_coresentiment_Data_pipeline/airflow/lib/python3.10/site-packages/snowflake/connector/vendored/urllib3/connection.py", line 545, in _match_hostname
    match_hostname(cert, asserted_hostname)
  File "/mnt/c/Users/zaina/Documents/Core_Data_Engineering/airflow/airflow_coresentiment_Data_pipeline/airflow/lib/python3.10/site-packages/snowflake/connector/vendored/urllib3/util/ssl_match_hostname.py", line 150, in match_hostname
    raise CertificateError(
snowflake.connector.vendored.urllib3.util.ssl_match_hostname.CertificateError: hostname 'ek32444.aws_eu_central_1.snowflakecomputing.com' doesn't match either of '*.prod3.us-west-2.snowflakecomputing.com', '*.us-west-2.snowflakecomputing.com', '*.global.snowflakecomputing.com', '*.snowflakecomputing.com', '*.prod3.us-west-2.aws.snowflakecomputing.com'

During handling of the above exception, another exception occurred:

Traceback (most recent call last):
  File "/mnt/c/Users/zaina/Documents/Core_Data_Engineering/airflow/airflow_coresentiment_Data_pipeline/airflow/lib/python3.10/site-packages/snowflake/connector/vendored/requests/adapters.py", line 486, in send
    resp = conn.urlopen(
  File "/mnt/c/Users/zaina/Documents/Core_Data_Engineering/airflow/airflow_coresentiment_Data_pipeline/airflow/lib/python3.10/site-packages/snowflake/connector/vendored/urllib3/connectionpool.py", line 827, in urlopen
    return self.urlopen(
  File "/mnt/c/Users/zaina/Documents/Core_Data_Engineering/airflow/airflow_coresentiment_Data_pipeline/airflow/lib/python3.10/site-packages/snowflake/connector/vendored/urllib3/connectionpool.py", line 799, in urlopen
    retries = retries.increment(
  File "/mnt/c/Users/zaina/Documents/Core_Data_Engineering/airflow/airflow_coresentiment_Data_pipeline/airflow/lib/python3.10/site-packages/snowflake/connector/vendored/urllib3/util/retry.py", line 592, in increment
    raise MaxRetryError(_pool, url, error or ResponseError(cause))
snowflake.connector.vendored.urllib3.exceptions.MaxRetryError: HTTPSConnectionPool(host='ek32444.aws_eu_central_1.snowflakecomputing.com', port=443): Max retries exceeded with url: /session/v1/login-request?request_id=f11ded67-d00e-4f57-b40d-108d35a8fac0&databaseName=country_data&schemaName=staging&warehouse=compute_wh&roleName=ACCOUNTADMIN&request_guid=035e55a2-8f6d-443e-9fd2-7237905f43b3 (Caused by SSLError(CertificateError("hostname 'ek32444.aws_eu_central_1.snowflakecomputing.com' doesn't match either of '*.prod3.us-west-2.snowflakecomputing.com', '*.us-west-2.snowflakecomputing.com', '*.global.snowflakecomputing.com', '*.snowflakecomputing.com', '*.prod3.us-west-2.aws.snowflakecomputing.com'")))

During handling of the above exception, another exception occurred:

Traceback (most recent call last):
  File "/mnt/c/Users/zaina/Documents/Core_Data_Engineering/airflow/airflow_coresentiment_Data_pipeline/airflow/lib/python3.10/site-packages/snowflake/connector/network.py", line 1072, in _request_exec
    raw_ret = session.request(
  File "/mnt/c/Users/zaina/Documents/Core_Data_Engineering/airflow/airflow_coresentiment_Data_pipeline/airflow/lib/python3.10/site-packages/snowflake/connector/vendored/requests/sessions.py", line 589, in request
    resp = self.send(prep, **send_kwargs)
  File "/mnt/c/Users/zaina/Documents/Core_Data_Engineering/airflow/airflow_coresentiment_Data_pipeline/airflow/lib/python3.10/site-packages/snowflake/connector/vendored/requests/sessions.py", line 703, in send
    r = adapter.send(request, **kwargs)
  File "/mnt/c/Users/zaina/Documents/Core_Data_Engineering/airflow/airflow_coresentiment_Data_pipeline/airflow/lib/python3.10/site-packages/snowflake/connector/vendored/requests/adapters.py", line 517, in send
    raise SSLError(e, request=request)
snowflake.connector.vendored.requests.exceptions.SSLError: HTTPSConnectionPool(host='ek32444.aws_eu_central_1.snowflakecomputing.com', port=443): Max retries exceeded with url: /session/v1/login-request?request_id=f11ded67-d00e-4f57-b40d-108d35a8fac0&databaseName=country_data&schemaName=staging&warehouse=compute_wh&roleName=ACCOUNTADMIN&request_guid=035e55a2-8f6d-443e-9fd2-7237905f43b3 (Caused by SSLError(CertificateError("hostname 'ek32444.aws_eu_central_1.snowflakecomputing.com' doesn't match either of '*.prod3.us-west-2.snowflakecomputing.com', '*.us-west-2.snowflakecomputing.com', '*.global.snowflakecomputing.com', '*.snowflakecomputing.com', '*.prod3.us-west-2.aws.snowflakecomputing.com'")))

During handling of the above exception, another exception occurred:

Traceback (most recent call last):
  File "/mnt/c/Users/zaina/Documents/Core_Data_Engineering/airflow/airflow_coresentiment_Data_pipeline/airflow/lib/python3.10/site-packages/snowflake/connector/connection.py", line 1415, in _authenticate
    auth.authenticate(
  File "/mnt/c/Users/zaina/Documents/Core_Data_Engineering/airflow/airflow_coresentiment_Data_pipeline/airflow/lib/python3.10/site-packages/snowflake/connector/auth/_auth.py", line 264, in authenticate
    ret = self._rest._post_request(
  File "/mnt/c/Users/zaina/Documents/Core_Data_Engineering/airflow/airflow_coresentiment_Data_pipeline/airflow/lib/python3.10/site-packages/snowflake/connector/network.py", line 740, in _post_request
    ret = self.fetch(
  File "/mnt/c/Users/zaina/Documents/Core_Data_Engineering/airflow/airflow_coresentiment_Data_pipeline/airflow/lib/python3.10/site-packages/snowflake/connector/network.py", line 855, in fetch
    ret = self._request_exec_wrapper(
  File "/mnt/c/Users/zaina/Documents/Core_Data_Engineering/airflow/airflow_coresentiment_Data_pipeline/airflow/lib/python3.10/site-packages/snowflake/connector/network.py", line 983, in _request_exec_wrapper
    raise e
  File "/mnt/c/Users/zaina/Documents/Core_Data_Engineering/airflow/airflow_coresentiment_Data_pipeline/airflow/lib/python3.10/site-packages/snowflake/connector/network.py", line 905, in _request_exec_wrapper
    return_object = self._request_exec(
  File "/mnt/c/Users/zaina/Documents/Core_Data_Engineering/airflow/airflow_coresentiment_Data_pipeline/airflow/lib/python3.10/site-packages/snowflake/connector/network.py", line 1142, in _request_exec
    Error.errorhandler_wrapper(
  File "/mnt/c/Users/zaina/Documents/Core_Data_Engineering/airflow/airflow_coresentiment_Data_pipeline/airflow/lib/python3.10/site-packages/snowflake/connector/errors.py", line 284, in errorhandler_wrapper
    handed_over = Error.hand_to_other_handler(
  File "/mnt/c/Users/zaina/Documents/Core_Data_Engineering/airflow/airflow_coresentiment_Data_pipeline/airflow/lib/python3.10/site-packages/snowflake/connector/errors.py", line 342, in hand_to_other_handler
    connection.errorhandler(connection, cursor, error_class, error_value)
  File "/mnt/c/Users/zaina/Documents/Core_Data_Engineering/airflow/airflow_coresentiment_Data_pipeline/airflow/lib/python3.10/site-packages/snowflake/connector/errors.py", line 215, in default_errorhandler
    raise error_class(
snowflake.connector.errors.OperationalError: 250003: 250003: Hit non-retryable SSL error, HTTPSConnectionPool(host='ek32444.aws_eu_central_1.snowflakecomputing.com', port=443): Max retries exceeded with url: /session/v1/login-request?request_id=f11ded67-d00e-4f57-b40d-108d35a8fac0&databaseName=country_data&schemaName=staging&warehouse=compute_wh&roleName=ACCOUNTADMIN&request_guid=035e55a2-8f6d-443e-9fd2-7237905f43b3 (Caused by SSLError(CertificateError("hostname 'ek32444.aws_eu_central_1.snowflakecomputing.com' doesn't match either of '*.prod3.us-west-2.snowflakecomputing.com', '*.us-west-2.snowflakecomputing.com', '*.global.snowflakecomputing.com', '*.snowflakecomputing.com', '*.prod3.us-west-2.aws.snowflakecomputing.com'"))).
Verify that the hostnames and port numbers in SYSTEM$ALLOWLIST are added to your firewall's allowed list.
To further troubleshoot your connection you may reference the following article: https://docs.snowflake.com/en/user-guide/client-connectivity-troubleshooting/overview.

The above exception was the direct cause of the following exception:

Traceback (most recent call last):
  File "/mnt/c/Users/zaina/Documents/Core_Data_Engineering/airflow/airflow_coresentiment_Data_pipeline/airflow/lib/python3.10/site-packages/airflow/task/task_runner/standard_task_runner.py", line 117, in _start_by_fork
    ret = args.func(args, dag=self.dag)
  File "/mnt/c/Users/zaina/Documents/Core_Data_Engineering/airflow/airflow_coresentiment_Data_pipeline/airflow/lib/python3.10/site-packages/airflow/cli/cli_config.py", line 49, in command
    return func(*args, **kwargs)
  File "/mnt/c/Users/zaina/Documents/Core_Data_Engineering/airflow/airflow_coresentiment_Data_pipeline/airflow/lib/python3.10/site-packages/airflow/utils/cli.py", line 115, in wrapper
    return f(*args, **kwargs)
  File "/mnt/c/Users/zaina/Documents/Core_Data_Engineering/airflow/airflow_coresentiment_Data_pipeline/airflow/lib/python3.10/site-packages/airflow/cli/commands/task_command.py", line 483, in task_run
    task_return_code = _run_task_by_selected_method(args, _dag, ti)
  File "/mnt/c/Users/zaina/Documents/Core_Data_Engineering/airflow/airflow_coresentiment_Data_pipeline/airflow/lib/python3.10/site-packages/airflow/cli/commands/task_command.py", line 256, in _run_task_by_selected_method
    return _run_raw_task(args, ti)
  File "/mnt/c/Users/zaina/Documents/Core_Data_Engineering/airflow/airflow_coresentiment_Data_pipeline/airflow/lib/python3.10/site-packages/airflow/cli/commands/task_command.py", line 341, in _run_raw_task
    return ti._run_raw_task(
  File "/mnt/c/Users/zaina/Documents/Core_Data_Engineering/airflow/airflow_coresentiment_Data_pipeline/airflow/lib/python3.10/site-packages/airflow/utils/session.py", line 97, in wrapper
    return func(*args, session=session, **kwargs)
  File "/mnt/c/Users/zaina/Documents/Core_Data_Engineering/airflow/airflow_coresentiment_Data_pipeline/airflow/lib/python3.10/site-packages/airflow/models/taskinstance.py", line 3004, in _run_raw_task
    return _run_raw_task(
  File "/mnt/c/Users/zaina/Documents/Core_Data_Engineering/airflow/airflow_coresentiment_Data_pipeline/airflow/lib/python3.10/site-packages/airflow/models/taskinstance.py", line 273, in _run_raw_task
    TaskInstance._execute_task_with_callbacks(
  File "/mnt/c/Users/zaina/Documents/Core_Data_Engineering/airflow/airflow_coresentiment_Data_pipeline/airflow/lib/python3.10/site-packages/airflow/models/taskinstance.py", line 3158, in _execute_task_with_callbacks
    result = self._execute_task(context, task_orig)
  File "/mnt/c/Users/zaina/Documents/Core_Data_Engineering/airflow/airflow_coresentiment_Data_pipeline/airflow/lib/python3.10/site-packages/airflow/models/taskinstance.py", line 3182, in _execute_task
    return _execute_task(self, context, task_orig)
  File "/mnt/c/Users/zaina/Documents/Core_Data_Engineering/airflow/airflow_coresentiment_Data_pipeline/airflow/lib/python3.10/site-packages/airflow/models/taskinstance.py", line 767, in _execute_task
    result = _execute_callable(context=context, **execute_callable_kwargs)
  File "/mnt/c/Users/zaina/Documents/Core_Data_Engineering/airflow/airflow_coresentiment_Data_pipeline/airflow/lib/python3.10/site-packages/airflow/models/taskinstance.py", line 733, in _execute_callable
    return ExecutionCallableRunner(
  File "/mnt/c/Users/zaina/Documents/Core_Data_Engineering/airflow/airflow_coresentiment_Data_pipeline/airflow/lib/python3.10/site-packages/airflow/utils/operator_helpers.py", line 252, in run
    return self.func(*args, **kwargs)
  File "/mnt/c/Users/zaina/Documents/Core_Data_Engineering/airflow/airflow_coresentiment_Data_pipeline/airflow/lib/python3.10/site-packages/airflow/models/baseoperator.py", line 406, in wrapper
    return func(self, *args, **kwargs)
  File "/mnt/c/Users/zaina/Documents/Core_Data_Engineering/airflow/airflow_coresentiment_Data_pipeline/airflow/lib/python3.10/site-packages/airflow/operators/python.py", line 238, in execute
    return_value = self.execute_callable()
  File "/mnt/c/Users/zaina/Documents/Core_Data_Engineering/airflow/airflow_coresentiment_Data_pipeline/airflow/lib/python3.10/site-packages/airflow/operators/python.py", line 256, in execute_callable
    return runner.run(*self.op_args, **self.op_kwargs)
  File "/mnt/c/Users/zaina/Documents/Core_Data_Engineering/airflow/airflow_coresentiment_Data_pipeline/airflow/lib/python3.10/site-packages/airflow/utils/operator_helpers.py", line 252, in run
    return self.func(*args, **kwargs)
  File "/mnt/c/Users/zaina/Documents/Core_Data_Engineering/capstone_project/airflow/dags/scripts/transform.py", line 95, in run_transformation
    load_function(
  File "/mnt/c/Users/zaina/Documents/Core_Data_Engineering/capstone_project/airflow/dags/scripts/load.py", line 74, in load_data_to_snowflake
    result = snowflake_hook.get_first(check_table_query)
  File "/mnt/c/Users/zaina/Documents/Core_Data_Engineering/airflow/airflow_coresentiment_Data_pipeline/airflow/lib/python3.10/site-packages/airflow/providers/common/sql/hooks/sql.py", line 367, in get_first
    return self.run(sql=sql, parameters=parameters, handler=fetch_one_handler)
  File "/mnt/c/Users/zaina/Documents/Core_Data_Engineering/airflow/airflow_coresentiment_Data_pipeline/airflow/lib/python3.10/site-packages/airflow/providers/snowflake/hooks/snowflake.py", line 429, in run
    with closing(self.get_conn()) as conn:
  File "/mnt/c/Users/zaina/Documents/Core_Data_Engineering/airflow/airflow_coresentiment_Data_pipeline/airflow/lib/python3.10/site-packages/airflow/providers/snowflake/hooks/snowflake.py", line 303, in get_conn
    conn = connector.connect(**conn_config)
  File "/mnt/c/Users/zaina/Documents/Core_Data_Engineering/airflow/airflow_coresentiment_Data_pipeline/airflow/lib/python3.10/site-packages/snowflake/connector/__init__.py", line 55, in Connect
    return SnowflakeConnection(**kwargs)
  File "/mnt/c/Users/zaina/Documents/Core_Data_Engineering/airflow/airflow_coresentiment_Data_pipeline/airflow/lib/python3.10/site-packages/snowflake/connector/connection.py", line 457, in __init__
    self.connect(**kwargs)
  File "/mnt/c/Users/zaina/Documents/Core_Data_Engineering/airflow/airflow_coresentiment_Data_pipeline/airflow/lib/python3.10/site-packages/snowflake/connector/connection.py", line 772, in connect
    self.__open_connection()
  File "/mnt/c/Users/zaina/Documents/Core_Data_Engineering/airflow/airflow_coresentiment_Data_pipeline/airflow/lib/python3.10/site-packages/snowflake/connector/connection.py", line 1100, in __open_connection
    self.authenticate_with_retry(self.auth_class)
  File "/mnt/c/Users/zaina/Documents/Core_Data_Engineering/airflow/airflow_coresentiment_Data_pipeline/airflow/lib/python3.10/site-packages/snowflake/connector/connection.py", line 1387, in authenticate_with_retry
    self._authenticate(auth_instance)
  File "/mnt/c/Users/zaina/Documents/Core_Data_Engineering/airflow/airflow_coresentiment_Data_pipeline/airflow/lib/python3.10/site-packages/snowflake/connector/connection.py", line 1461, in _authenticate
    raise auth_op from e
  File "/mnt/c/Users/zaina/Documents/Core_Data_Engineering/airflow/airflow_coresentiment_Data_pipeline/airflow/lib/python3.10/site-packages/snowflake/connector/connection.py", line 1436, in _authenticate
    auth_instance.handle_timeout(
  File "/mnt/c/Users/zaina/Documents/Core_Data_Engineering/airflow/airflow_coresentiment_Data_pipeline/airflow/lib/python3.10/site-packages/snowflake/connector/auth/by_plugin.py", line 212, in handle_timeout
    raise error
snowflake.connector.errors.OperationalError: 250001: 250001: Could not connect to Snowflake backend after 2 attempt(s).Aborting
Verify that the hostnames and port numbers in SYSTEM$ALLOWLIST are added to your firewall's allowed list.
To further troubleshoot your connection you may reference the following article: https://docs.snowflake.com/en/user-guide/client-connectivity-troubleshooting/overview.
[2024-11-19T20:47:56.036+0100] {local_task_job_runner.py:266} INFO - Task exited with return code 1
[2024-11-19T20:47:56.071+0100] {taskinstance.py:3900} INFO - 0 downstream tasks scheduled from follow-on schedule check
[2024-11-19T20:47:56.075+0100] {local_task_job_runner.py:245} INFO - ::endgroup::
