[2024-11-19T02:55:05.124+0100] {local_task_job_runner.py:123} INFO - ::group::Pre task execution logs
[2024-11-19T02:55:05.165+0100] {taskinstance.py:2612} INFO - Dependencies all met for dep_context=non-requeueable deps ti=<TaskInstance: etl_pipeline_to_snowflake.transform_data manual__2024-11-19T00:21:47.385967+00:00 [queued]>
[2024-11-19T02:55:05.192+0100] {taskinstance.py:2612} INFO - Dependencies all met for dep_context=requeueable deps ti=<TaskInstance: etl_pipeline_to_snowflake.transform_data manual__2024-11-19T00:21:47.385967+00:00 [queued]>
[2024-11-19T02:55:05.196+0100] {taskinstance.py:2865} INFO - Starting attempt 4 of 4
[2024-11-19T02:55:05.268+0100] {taskinstance.py:2888} INFO - Executing <Task(PythonOperator): transform_data> on 2024-11-19 00:21:47.385967+00:00
[2024-11-19T02:55:05.283+0100] {standard_task_runner.py:72} INFO - Started process 216725 to run task
[2024-11-19T02:55:05.292+0100] {standard_task_runner.py:104} INFO - Running: ['airflow', 'tasks', 'run', 'etl_pipeline_to_snowflake', 'transform_data', 'manual__2024-11-19T00:21:47.385967+00:00', '--job-id', '29', '--raw', '--subdir', 'DAGS_FOLDER/staging_data_dag.py', '--cfg-path', '/tmp/tmp_af7tngs']
[2024-11-19T02:55:05.297+0100] {standard_task_runner.py:105} INFO - Job 29: Subtask transform_data
[2024-11-19T02:55:05.435+0100] {task_command.py:467} INFO - Running <TaskInstance: etl_pipeline_to_snowflake.transform_data manual__2024-11-19T00:21:47.385967+00:00 [running]> on host zainab.
[2024-11-19T02:55:05.627+0100] {taskinstance.py:3131} INFO - Exporting env vars: AIRFLOW_CTX_DAG_OWNER='airflow' AIRFLOW_CTX_DAG_ID='etl_pipeline_to_snowflake' AIRFLOW_CTX_TASK_ID='transform_data' AIRFLOW_CTX_EXECUTION_DATE='2024-11-19T00:21:47.385967+00:00' AIRFLOW_CTX_TRY_NUMBER='4' AIRFLOW_CTX_DAG_RUN_ID='manual__2024-11-19T00:21:47.385967+00:00'
[2024-11-19T02:55:05.631+0100] {logging_mixin.py:190} INFO - Task instance is in running state
[2024-11-19T02:55:05.634+0100] {logging_mixin.py:190} INFO -  Previous state of the Task instance: queued
[2024-11-19T02:55:05.638+0100] {logging_mixin.py:190} INFO - Current task name:transform_data state:running start_date:2024-11-19 01:55:05.169211+00:00
[2024-11-19T02:55:05.642+0100] {logging_mixin.py:190} INFO - Dag name:etl_pipeline_to_snowflake and current dag run status:running
[2024-11-19T02:55:05.645+0100] {taskinstance.py:731} INFO - ::endgroup::
[2024-11-19T02:55:05.649+0100] {taskinstance.py:3310} ERROR - Task failed with exception
Traceback (most recent call last):
  File "/mnt/c/Users/zaina/Documents/Core_Data_Engineering/airflow/airflow_coresentiment_Data_pipeline/airflow/lib/python3.10/site-packages/airflow/models/taskinstance.py", line 767, in _execute_task
    result = _execute_callable(context=context, **execute_callable_kwargs)
  File "/mnt/c/Users/zaina/Documents/Core_Data_Engineering/airflow/airflow_coresentiment_Data_pipeline/airflow/lib/python3.10/site-packages/airflow/models/taskinstance.py", line 733, in _execute_callable
    return ExecutionCallableRunner(
  File "/mnt/c/Users/zaina/Documents/Core_Data_Engineering/airflow/airflow_coresentiment_Data_pipeline/airflow/lib/python3.10/site-packages/airflow/utils/operator_helpers.py", line 252, in run
    return self.func(*args, **kwargs)
  File "/mnt/c/Users/zaina/Documents/Core_Data_Engineering/airflow/airflow_coresentiment_Data_pipeline/airflow/lib/python3.10/site-packages/airflow/models/baseoperator.py", line 406, in wrapper
    return func(self, *args, **kwargs)
  File "/mnt/c/Users/zaina/Documents/Core_Data_Engineering/airflow/airflow_coresentiment_Data_pipeline/airflow/lib/python3.10/site-packages/airflow/operators/python.py", line 238, in execute
    return_value = self.execute_callable()
  File "/mnt/c/Users/zaina/Documents/Core_Data_Engineering/airflow/airflow_coresentiment_Data_pipeline/airflow/lib/python3.10/site-packages/airflow/operators/python.py", line 256, in execute_callable
    return runner.run(*self.op_args, **self.op_kwargs)
  File "/mnt/c/Users/zaina/Documents/Core_Data_Engineering/airflow/airflow_coresentiment_Data_pipeline/airflow/lib/python3.10/site-packages/airflow/utils/operator_helpers.py", line 252, in run
    return self.func(*args, **kwargs)
TypeError: transform_data_s3() missing 1 required positional argument: 'data'
[2024-11-19T02:55:05.733+0100] {logging_mixin.py:190} INFO - Task instance in failure state
[2024-11-19T02:55:05.738+0100] {logging_mixin.py:190} INFO - Task start:2024-11-19 01:55:05.169211+00:00 end:2024-11-19 01:55:05.732428+00:00 duration:0.563217
[2024-11-19T02:55:05.744+0100] {logging_mixin.py:190} INFO - Task:<Task(PythonOperator): transform_data> dag:<DAG: etl_pipeline_to_snowflake> dagrun:<DagRun etl_pipeline_to_snowflake @ 2024-11-19 00:21:47.385967+00:00: manual__2024-11-19T00:21:47.385967+00:00, state:running, queued_at: 2024-11-19 01:47:56.198828+00:00. externally triggered: True>
[2024-11-19T02:55:05.751+0100] {logging_mixin.py:190} INFO - Failure caused by transform_data_s3() missing 1 required positional argument: 'data'
[2024-11-19T02:55:05.756+0100] {taskinstance.py:1225} INFO - Marking task as FAILED. dag_id=etl_pipeline_to_snowflake, task_id=transform_data, run_id=manual__2024-11-19T00:21:47.385967+00:00, execution_date=20241119T002147, start_date=20241119T015505, end_date=20241119T015505
[2024-11-19T02:55:05.846+0100] {taskinstance.py:340} INFO - ::group::Post task execution logs
[2024-11-19T02:55:05.850+0100] {standard_task_runner.py:124} ERROR - Failed to execute job 29 for task transform_data (transform_data_s3() missing 1 required positional argument: 'data'; 216725)
Traceback (most recent call last):
  File "/mnt/c/Users/zaina/Documents/Core_Data_Engineering/airflow/airflow_coresentiment_Data_pipeline/airflow/lib/python3.10/site-packages/airflow/task/task_runner/standard_task_runner.py", line 117, in _start_by_fork
    ret = args.func(args, dag=self.dag)
  File "/mnt/c/Users/zaina/Documents/Core_Data_Engineering/airflow/airflow_coresentiment_Data_pipeline/airflow/lib/python3.10/site-packages/airflow/cli/cli_config.py", line 49, in command
    return func(*args, **kwargs)
  File "/mnt/c/Users/zaina/Documents/Core_Data_Engineering/airflow/airflow_coresentiment_Data_pipeline/airflow/lib/python3.10/site-packages/airflow/utils/cli.py", line 115, in wrapper
    return f(*args, **kwargs)
  File "/mnt/c/Users/zaina/Documents/Core_Data_Engineering/airflow/airflow_coresentiment_Data_pipeline/airflow/lib/python3.10/site-packages/airflow/cli/commands/task_command.py", line 483, in task_run
    task_return_code = _run_task_by_selected_method(args, _dag, ti)
  File "/mnt/c/Users/zaina/Documents/Core_Data_Engineering/airflow/airflow_coresentiment_Data_pipeline/airflow/lib/python3.10/site-packages/airflow/cli/commands/task_command.py", line 256, in _run_task_by_selected_method
    return _run_raw_task(args, ti)
  File "/mnt/c/Users/zaina/Documents/Core_Data_Engineering/airflow/airflow_coresentiment_Data_pipeline/airflow/lib/python3.10/site-packages/airflow/cli/commands/task_command.py", line 341, in _run_raw_task
    return ti._run_raw_task(
  File "/mnt/c/Users/zaina/Documents/Core_Data_Engineering/airflow/airflow_coresentiment_Data_pipeline/airflow/lib/python3.10/site-packages/airflow/utils/session.py", line 97, in wrapper
    return func(*args, session=session, **kwargs)
  File "/mnt/c/Users/zaina/Documents/Core_Data_Engineering/airflow/airflow_coresentiment_Data_pipeline/airflow/lib/python3.10/site-packages/airflow/models/taskinstance.py", line 3004, in _run_raw_task
    return _run_raw_task(
  File "/mnt/c/Users/zaina/Documents/Core_Data_Engineering/airflow/airflow_coresentiment_Data_pipeline/airflow/lib/python3.10/site-packages/airflow/models/taskinstance.py", line 273, in _run_raw_task
    TaskInstance._execute_task_with_callbacks(
  File "/mnt/c/Users/zaina/Documents/Core_Data_Engineering/airflow/airflow_coresentiment_Data_pipeline/airflow/lib/python3.10/site-packages/airflow/models/taskinstance.py", line 3158, in _execute_task_with_callbacks
    result = self._execute_task(context, task_orig)
  File "/mnt/c/Users/zaina/Documents/Core_Data_Engineering/airflow/airflow_coresentiment_Data_pipeline/airflow/lib/python3.10/site-packages/airflow/models/taskinstance.py", line 3182, in _execute_task
    return _execute_task(self, context, task_orig)
  File "/mnt/c/Users/zaina/Documents/Core_Data_Engineering/airflow/airflow_coresentiment_Data_pipeline/airflow/lib/python3.10/site-packages/airflow/models/taskinstance.py", line 767, in _execute_task
    result = _execute_callable(context=context, **execute_callable_kwargs)
  File "/mnt/c/Users/zaina/Documents/Core_Data_Engineering/airflow/airflow_coresentiment_Data_pipeline/airflow/lib/python3.10/site-packages/airflow/models/taskinstance.py", line 733, in _execute_callable
    return ExecutionCallableRunner(
  File "/mnt/c/Users/zaina/Documents/Core_Data_Engineering/airflow/airflow_coresentiment_Data_pipeline/airflow/lib/python3.10/site-packages/airflow/utils/operator_helpers.py", line 252, in run
    return self.func(*args, **kwargs)
  File "/mnt/c/Users/zaina/Documents/Core_Data_Engineering/airflow/airflow_coresentiment_Data_pipeline/airflow/lib/python3.10/site-packages/airflow/models/baseoperator.py", line 406, in wrapper
    return func(self, *args, **kwargs)
  File "/mnt/c/Users/zaina/Documents/Core_Data_Engineering/airflow/airflow_coresentiment_Data_pipeline/airflow/lib/python3.10/site-packages/airflow/operators/python.py", line 238, in execute
    return_value = self.execute_callable()
  File "/mnt/c/Users/zaina/Documents/Core_Data_Engineering/airflow/airflow_coresentiment_Data_pipeline/airflow/lib/python3.10/site-packages/airflow/operators/python.py", line 256, in execute_callable
    return runner.run(*self.op_args, **self.op_kwargs)
  File "/mnt/c/Users/zaina/Documents/Core_Data_Engineering/airflow/airflow_coresentiment_Data_pipeline/airflow/lib/python3.10/site-packages/airflow/utils/operator_helpers.py", line 252, in run
    return self.func(*args, **kwargs)
TypeError: transform_data_s3() missing 1 required positional argument: 'data'
[2024-11-19T02:55:05.911+0100] {local_task_job_runner.py:266} INFO - Task exited with return code 1
[2024-11-19T02:55:05.944+0100] {taskinstance.py:3900} INFO - 0 downstream tasks scheduled from follow-on schedule check
[2024-11-19T02:55:05.980+0100] {local_task_job_runner.py:245} INFO - ::endgroup::
