[2024-11-19T04:25:15.410+0100] {local_task_job_runner.py:123} INFO - ::group::Pre task execution logs
[2024-11-19T04:25:15.437+0100] {taskinstance.py:2612} INFO - Dependencies all met for dep_context=non-requeueable deps ti=<TaskInstance: etl_pipeline_to_snowflake.transform_data manual__2024-11-19T00:21:47.385967+00:00 [queued]>
[2024-11-19T04:25:15.462+0100] {taskinstance.py:2612} INFO - Dependencies all met for dep_context=requeueable deps ti=<TaskInstance: etl_pipeline_to_snowflake.transform_data manual__2024-11-19T00:21:47.385967+00:00 [queued]>
[2024-11-19T04:25:15.464+0100] {taskinstance.py:2865} INFO - Starting attempt 8 of 8
[2024-11-19T04:25:15.508+0100] {taskinstance.py:2888} INFO - Executing <Task(PythonOperator): transform_data> on 2024-11-19 00:21:47.385967+00:00
[2024-11-19T04:25:15.537+0100] {standard_task_runner.py:72} INFO - Started process 218238 to run task
[2024-11-19T04:25:15.544+0100] {standard_task_runner.py:104} INFO - Running: ['airflow', 'tasks', 'run', 'etl_pipeline_to_snowflake', 'transform_data', 'manual__2024-11-19T00:21:47.385967+00:00', '--job-id', '35', '--raw', '--subdir', 'DAGS_FOLDER/staging_data_dag.py', '--cfg-path', '/tmp/tmpi8esf435']
[2024-11-19T04:25:15.548+0100] {standard_task_runner.py:105} INFO - Job 35: Subtask transform_data
[2024-11-19T04:25:15.644+0100] {task_command.py:467} INFO - Running <TaskInstance: etl_pipeline_to_snowflake.transform_data manual__2024-11-19T00:21:47.385967+00:00 [running]> on host zainab.
[2024-11-19T04:25:15.768+0100] {taskinstance.py:3131} INFO - Exporting env vars: AIRFLOW_CTX_DAG_OWNER='airflow' AIRFLOW_CTX_DAG_ID='etl_pipeline_to_snowflake' AIRFLOW_CTX_TASK_ID='transform_data' AIRFLOW_CTX_EXECUTION_DATE='2024-11-19T00:21:47.385967+00:00' AIRFLOW_CTX_TRY_NUMBER='8' AIRFLOW_CTX_DAG_RUN_ID='manual__2024-11-19T00:21:47.385967+00:00'
[2024-11-19T04:25:15.770+0100] {logging_mixin.py:190} INFO - Task instance is in running state
[2024-11-19T04:25:15.773+0100] {logging_mixin.py:190} INFO -  Previous state of the Task instance: queued
[2024-11-19T04:25:15.774+0100] {logging_mixin.py:190} INFO - Current task name:transform_data state:running start_date:2024-11-19 03:25:15.443386+00:00
[2024-11-19T04:25:15.776+0100] {logging_mixin.py:190} INFO - Dag name:etl_pipeline_to_snowflake and current dag run status:running
[2024-11-19T04:25:15.777+0100] {taskinstance.py:731} INFO - ::endgroup::
[2024-11-19T04:25:15.779+0100] {taskinstance.py:3310} ERROR - Task failed with exception
Traceback (most recent call last):
  File "/mnt/c/Users/zaina/Documents/Core_Data_Engineering/airflow/airflow_coresentiment_Data_pipeline/airflow/lib/python3.10/site-packages/airflow/models/taskinstance.py", line 767, in _execute_task
    result = _execute_callable(context=context, **execute_callable_kwargs)
  File "/mnt/c/Users/zaina/Documents/Core_Data_Engineering/airflow/airflow_coresentiment_Data_pipeline/airflow/lib/python3.10/site-packages/airflow/models/taskinstance.py", line 733, in _execute_callable
    return ExecutionCallableRunner(
  File "/mnt/c/Users/zaina/Documents/Core_Data_Engineering/airflow/airflow_coresentiment_Data_pipeline/airflow/lib/python3.10/site-packages/airflow/utils/operator_helpers.py", line 252, in run
    return self.func(*args, **kwargs)
  File "/mnt/c/Users/zaina/Documents/Core_Data_Engineering/airflow/airflow_coresentiment_Data_pipeline/airflow/lib/python3.10/site-packages/airflow/models/baseoperator.py", line 406, in wrapper
    return func(self, *args, **kwargs)
  File "/mnt/c/Users/zaina/Documents/Core_Data_Engineering/airflow/airflow_coresentiment_Data_pipeline/airflow/lib/python3.10/site-packages/airflow/operators/python.py", line 238, in execute
    return_value = self.execute_callable()
  File "/mnt/c/Users/zaina/Documents/Core_Data_Engineering/airflow/airflow_coresentiment_Data_pipeline/airflow/lib/python3.10/site-packages/airflow/operators/python.py", line 256, in execute_callable
    return runner.run(*self.op_args, **self.op_kwargs)
  File "/mnt/c/Users/zaina/Documents/Core_Data_Engineering/airflow/airflow_coresentiment_Data_pipeline/airflow/lib/python3.10/site-packages/airflow/utils/operator_helpers.py", line 252, in run
    return self.func(*args, **kwargs)
TypeError: transform_data_s3() missing 1 required positional argument: 'data'
[2024-11-19T04:25:15.814+0100] {logging_mixin.py:190} INFO - Task instance in failure state
[2024-11-19T04:25:15.817+0100] {logging_mixin.py:190} INFO - Task start:2024-11-19 03:25:15.443386+00:00 end:2024-11-19 03:25:15.814413+00:00 duration:0.371027
[2024-11-19T04:25:15.819+0100] {logging_mixin.py:190} INFO - Task:<Task(PythonOperator): transform_data> dag:<DAG: etl_pipeline_to_snowflake> dagrun:<DagRun etl_pipeline_to_snowflake @ 2024-11-19 00:21:47.385967+00:00: manual__2024-11-19T00:21:47.385967+00:00, state:running, queued_at: 2024-11-19 02:37:35.719230+00:00. externally triggered: True>
[2024-11-19T04:25:15.822+0100] {logging_mixin.py:190} INFO - Failure caused by transform_data_s3() missing 1 required positional argument: 'data'
[2024-11-19T04:25:15.825+0100] {taskinstance.py:1225} INFO - Marking task as FAILED. dag_id=etl_pipeline_to_snowflake, task_id=transform_data, run_id=manual__2024-11-19T00:21:47.385967+00:00, execution_date=20241119T002147, start_date=20241119T032515, end_date=20241119T032515
[2024-11-19T04:25:15.870+0100] {taskinstance.py:340} INFO - ::group::Post task execution logs
[2024-11-19T04:25:15.873+0100] {standard_task_runner.py:124} ERROR - Failed to execute job 35 for task transform_data (transform_data_s3() missing 1 required positional argument: 'data'; 218238)
Traceback (most recent call last):
  File "/mnt/c/Users/zaina/Documents/Core_Data_Engineering/airflow/airflow_coresentiment_Data_pipeline/airflow/lib/python3.10/site-packages/airflow/task/task_runner/standard_task_runner.py", line 117, in _start_by_fork
    ret = args.func(args, dag=self.dag)
  File "/mnt/c/Users/zaina/Documents/Core_Data_Engineering/airflow/airflow_coresentiment_Data_pipeline/airflow/lib/python3.10/site-packages/airflow/cli/cli_config.py", line 49, in command
    return func(*args, **kwargs)
  File "/mnt/c/Users/zaina/Documents/Core_Data_Engineering/airflow/airflow_coresentiment_Data_pipeline/airflow/lib/python3.10/site-packages/airflow/utils/cli.py", line 115, in wrapper
    return f(*args, **kwargs)
  File "/mnt/c/Users/zaina/Documents/Core_Data_Engineering/airflow/airflow_coresentiment_Data_pipeline/airflow/lib/python3.10/site-packages/airflow/cli/commands/task_command.py", line 483, in task_run
    task_return_code = _run_task_by_selected_method(args, _dag, ti)
  File "/mnt/c/Users/zaina/Documents/Core_Data_Engineering/airflow/airflow_coresentiment_Data_pipeline/airflow/lib/python3.10/site-packages/airflow/cli/commands/task_command.py", line 256, in _run_task_by_selected_method
    return _run_raw_task(args, ti)
  File "/mnt/c/Users/zaina/Documents/Core_Data_Engineering/airflow/airflow_coresentiment_Data_pipeline/airflow/lib/python3.10/site-packages/airflow/cli/commands/task_command.py", line 341, in _run_raw_task
    return ti._run_raw_task(
  File "/mnt/c/Users/zaina/Documents/Core_Data_Engineering/airflow/airflow_coresentiment_Data_pipeline/airflow/lib/python3.10/site-packages/airflow/utils/session.py", line 97, in wrapper
    return func(*args, session=session, **kwargs)
  File "/mnt/c/Users/zaina/Documents/Core_Data_Engineering/airflow/airflow_coresentiment_Data_pipeline/airflow/lib/python3.10/site-packages/airflow/models/taskinstance.py", line 3004, in _run_raw_task
    return _run_raw_task(
  File "/mnt/c/Users/zaina/Documents/Core_Data_Engineering/airflow/airflow_coresentiment_Data_pipeline/airflow/lib/python3.10/site-packages/airflow/models/taskinstance.py", line 273, in _run_raw_task
    TaskInstance._execute_task_with_callbacks(
  File "/mnt/c/Users/zaina/Documents/Core_Data_Engineering/airflow/airflow_coresentiment_Data_pipeline/airflow/lib/python3.10/site-packages/airflow/models/taskinstance.py", line 3158, in _execute_task_with_callbacks
    result = self._execute_task(context, task_orig)
  File "/mnt/c/Users/zaina/Documents/Core_Data_Engineering/airflow/airflow_coresentiment_Data_pipeline/airflow/lib/python3.10/site-packages/airflow/models/taskinstance.py", line 3182, in _execute_task
    return _execute_task(self, context, task_orig)
  File "/mnt/c/Users/zaina/Documents/Core_Data_Engineering/airflow/airflow_coresentiment_Data_pipeline/airflow/lib/python3.10/site-packages/airflow/models/taskinstance.py", line 767, in _execute_task
    result = _execute_callable(context=context, **execute_callable_kwargs)
  File "/mnt/c/Users/zaina/Documents/Core_Data_Engineering/airflow/airflow_coresentiment_Data_pipeline/airflow/lib/python3.10/site-packages/airflow/models/taskinstance.py", line 733, in _execute_callable
    return ExecutionCallableRunner(
  File "/mnt/c/Users/zaina/Documents/Core_Data_Engineering/airflow/airflow_coresentiment_Data_pipeline/airflow/lib/python3.10/site-packages/airflow/utils/operator_helpers.py", line 252, in run
    return self.func(*args, **kwargs)
  File "/mnt/c/Users/zaina/Documents/Core_Data_Engineering/airflow/airflow_coresentiment_Data_pipeline/airflow/lib/python3.10/site-packages/airflow/models/baseoperator.py", line 406, in wrapper
    return func(self, *args, **kwargs)
  File "/mnt/c/Users/zaina/Documents/Core_Data_Engineering/airflow/airflow_coresentiment_Data_pipeline/airflow/lib/python3.10/site-packages/airflow/operators/python.py", line 238, in execute
    return_value = self.execute_callable()
  File "/mnt/c/Users/zaina/Documents/Core_Data_Engineering/airflow/airflow_coresentiment_Data_pipeline/airflow/lib/python3.10/site-packages/airflow/operators/python.py", line 256, in execute_callable
    return runner.run(*self.op_args, **self.op_kwargs)
  File "/mnt/c/Users/zaina/Documents/Core_Data_Engineering/airflow/airflow_coresentiment_Data_pipeline/airflow/lib/python3.10/site-packages/airflow/utils/operator_helpers.py", line 252, in run
    return self.func(*args, **kwargs)
TypeError: transform_data_s3() missing 1 required positional argument: 'data'
[2024-11-19T04:25:15.919+0100] {local_task_job_runner.py:266} INFO - Task exited with return code 1
[2024-11-19T04:25:15.953+0100] {taskinstance.py:3900} INFO - 0 downstream tasks scheduled from follow-on schedule check
[2024-11-19T04:25:15.974+0100] {local_task_job_runner.py:245} INFO - ::endgroup::
